{"uuid": "5a7679cb-c549-4812-9c04-bb308304c787", "children": ["61243c24-8a20-406d-98f8-6c84bdaaf1a8", "ffcb5021-dfa8-4247-a754-f5973f1467e2", "a3ba30fd-b9bb-4a99-8071-3bc079fbece6", "9945321f-9fa7-4268-bd8e-c3b1f2387bc7"], "befores": [{"name": "beforeClass", "status": "broken", "statusDetails": {"message": "selenium.common.exceptions.WebDriverException: Message: An unknown server-side error occurred while processing the command. Original error: Could not find a connected Android device in 20000ms\nStacktrace:\nUnknownError: An unknown server-side error occurred while processing the command. Original error: Could not find a connected Android device in 20000ms\n    at getResponseForW3CError (C:\\Users\\chinm\\AppData\\Roaming\\npm\\node_modules\\appium\\node_modules\\@appium\\base-driver\\lib\\protocol\\errors.js:1143:9)\n    at asyncHandler (C:\\Users\\chinm\\AppData\\Roaming\\npm\\node_modules\\appium\\node_modules\\@appium\\base-driver\\lib\\protocol\\protocol.js:485:57)\n", "trace": "  File \"C:\\Users\\chinm\\PycharmProjects\\Appium_Automation\\.venv\\Lib\\site-packages\\pluggy\\_callers.py\", line 167, in _multicall\n    teardown.throw(outcome._exception)\n    ~~~~~~~~~~~~~~^^^^^^^^^^^^^^^^^^^^\n  File \"C:\\Users\\chinm\\PycharmProjects\\Appium_Automation\\.venv\\Lib\\site-packages\\_pytest\\setuponly.py\", line 36, in pytest_fixture_setup\n    return (yield)\n            ^^^^^\n  File \"C:\\Users\\chinm\\PycharmProjects\\Appium_Automation\\.venv\\Lib\\site-packages\\pluggy\\_callers.py\", line 103, in _multicall\n    res = hook_impl.function(*args)\n  File \"C:\\Users\\chinm\\PycharmProjects\\Appium_Automation\\.venv\\Lib\\site-packages\\_pytest\\fixtures.py\", line 1140, in pytest_fixture_setup\n    result = call_fixture_func(fixturefunc, request, kwargs)\n  File \"C:\\Users\\chinm\\PycharmProjects\\Appium_Automation\\.venv\\Lib\\site-packages\\_pytest\\fixtures.py\", line 891, in call_fixture_func\n    fixture_result = next(generator)\n  File \"C:\\Users\\chinm\\PycharmProjects\\Appium_Automation\\tests\\conftest.py\", line 9, in beforeClass\n    driver= driver1.getDriverMethod()\n  File \"C:\\Users\\chinm\\PycharmProjects\\Appium_Automation\\base\\DriverClass.py\", line 42, in getDriverMethod\n    driver = webdriver.Remote('http://127.0.0.1:4723', options=options, direct_connection=True)\n  File \"C:\\Users\\chinm\\PycharmProjects\\Appium_Automation\\.venv\\Lib\\site-packages\\appium\\webdriver\\webdriver.py\", line 227, in __init__\n    super().__init__(\n    ~~~~~~~~~~~~~~~~^\n        command_executor=command_executor,\n        ^^^^^^^^^^^^^^^^^^^^^^^^^^^^^^^^^^\n    ...<3 lines>...\n        client_config=client_config,\n        ^^^^^^^^^^^^^^^^^^^^^^^^^^^^\n    )\n    ^\n  File \"C:\\Users\\chinm\\PycharmProjects\\Appium_Automation\\.venv\\Lib\\site-packages\\selenium\\webdriver\\remote\\webdriver.py\", line 250, in __init__\n    self.start_session(capabilities)\n    ~~~~~~~~~~~~~~~~~~^^^^^^^^^^^^^^\n  File \"C:\\Users\\chinm\\PycharmProjects\\Appium_Automation\\.venv\\Lib\\site-packages\\appium\\webdriver\\webdriver.py\", line 319, in start_session\n    response = self.execute(RemoteCommand.NEW_SESSION, w3c_caps)\n  File \"C:\\Users\\chinm\\PycharmProjects\\Appium_Automation\\.venv\\Lib\\site-packages\\selenium\\webdriver\\remote\\webdriver.py\", line 429, in execute\n    self.error_handler.check_response(response)\n    ~~~~~~~~~~~~~~~~~~~~~~~~~~~~~~~~~^^^^^^^^^^\n  File \"C:\\Users\\chinm\\PycharmProjects\\Appium_Automation\\.venv\\Lib\\site-packages\\selenium\\webdriver\\remote\\errorhandler.py\", line 232, in check_response\n    raise exception_class(message, screen, stacktrace)\n"}, "start": 1739874587207, "stop": 1739874613920}], "start": 1739874587207, "stop": 1739874614155}