{"uuid": "cc0e6e9d-6402-4cb7-b9aa-1eace0ea360c", "children": ["3d57b91d-d4a5-48f5-9d9b-5e7ba711ad4c", "1248e380-b0ce-4ac2-a453-4cea561c6707"], "befores": [{"name": "beforeClass", "status": "broken", "statusDetails": {"message": "selenium.common.exceptions.WebDriverException: Message: An unknown server-side error occurred while processing the command. Original error: The instrumentation process cannot be initialized. Make sure the application under test does not crash and investigate the logcat output.\nStacktrace:\nUnknownError: An unknown server-side error occurred while processing the command. Original error: The instrumentation process cannot be initialized. Make sure the application under test does not crash and investigate the logcat output.\n    at getResponseForW3CError (C:\\Users\\chinm\\AppData\\Roaming\\npm\\node_modules\\appium\\node_modules\\@appium\\base-driver\\lib\\protocol\\errors.js:1143:9)\n    at asyncHandler (C:\\Users\\chinm\\AppData\\Roaming\\npm\\node_modules\\appium\\node_modules\\@appium\\base-driver\\lib\\protocol\\protocol.js:485:57)\n", "trace": "  File \"C:\\Users\\chinm\\PycharmProjects\\Appium_Automation\\.venv\\Lib\\site-packages\\pluggy\\_callers.py\", line 167, in _multicall\n    teardown.throw(outcome._exception)\n    ~~~~~~~~~~~~~~^^^^^^^^^^^^^^^^^^^^\n  File \"C:\\Users\\chinm\\PycharmProjects\\Appium_Automation\\.venv\\Lib\\site-packages\\_pytest\\setuponly.py\", line 36, in pytest_fixture_setup\n    return (yield)\n            ^^^^^\n  File \"C:\\Users\\chinm\\PycharmProjects\\Appium_Automation\\.venv\\Lib\\site-packages\\pluggy\\_callers.py\", line 103, in _multicall\n    res = hook_impl.function(*args)\n  File \"C:\\Users\\chinm\\PycharmProjects\\Appium_Automation\\.venv\\Lib\\site-packages\\_pytest\\fixtures.py\", line 1140, in pytest_fixture_setup\n    result = call_fixture_func(fixturefunc, request, kwargs)\n  File \"C:\\Users\\chinm\\PycharmProjects\\Appium_Automation\\.venv\\Lib\\site-packages\\_pytest\\fixtures.py\", line 891, in call_fixture_func\n    fixture_result = next(generator)\n  File \"C:\\Users\\chinm\\PycharmProjects\\Appium_Automation\\tests\\conftest.py\", line 9, in beforeClass\n    driver= driver1.getDriverMethod()\n  File \"C:\\Users\\chinm\\PycharmProjects\\Appium_Automation\\base\\DriverClass.py\", line 42, in getDriverMethod\n    driver = webdriver.Remote('http://127.0.0.1:4723', options=options, direct_connection=True)\n  File \"C:\\Users\\chinm\\PycharmProjects\\Appium_Automation\\.venv\\Lib\\site-packages\\appium\\webdriver\\webdriver.py\", line 227, in __init__\n    super().__init__(\n    ~~~~~~~~~~~~~~~~^\n        command_executor=command_executor,\n        ^^^^^^^^^^^^^^^^^^^^^^^^^^^^^^^^^^\n    ...<3 lines>...\n        client_config=client_config,\n        ^^^^^^^^^^^^^^^^^^^^^^^^^^^^\n    )\n    ^\n  File \"C:\\Users\\chinm\\PycharmProjects\\Appium_Automation\\.venv\\Lib\\site-packages\\selenium\\webdriver\\remote\\webdriver.py\", line 250, in __init__\n    self.start_session(capabilities)\n    ~~~~~~~~~~~~~~~~~~^^^^^^^^^^^^^^\n  File \"C:\\Users\\chinm\\PycharmProjects\\Appium_Automation\\.venv\\Lib\\site-packages\\appium\\webdriver\\webdriver.py\", line 319, in start_session\n    response = self.execute(RemoteCommand.NEW_SESSION, w3c_caps)\n  File \"C:\\Users\\chinm\\PycharmProjects\\Appium_Automation\\.venv\\Lib\\site-packages\\selenium\\webdriver\\remote\\webdriver.py\", line 429, in execute\n    self.error_handler.check_response(response)\n    ~~~~~~~~~~~~~~~~~~~~~~~~~~~~~~~~~^^^^^^^^^^\n  File \"C:\\Users\\chinm\\PycharmProjects\\Appium_Automation\\.venv\\Lib\\site-packages\\selenium\\webdriver\\remote\\errorhandler.py\", line 232, in check_response\n    raise exception_class(message, screen, stacktrace)\n"}, "start": 1739940841919, "stop": 1739940890300}], "start": 1739940841919, "stop": 1739940890422}