[33mWARNING [0m urllib3.connectionpool:connectionpool.py:868 Retrying (Retry(total=2, connect=None, read=None, redirect=None, status=None)) after connection broken by 'ConnectTimeoutError(<urllib3.connection.HTTPConnection object at 0x000002989EDA1A90>, 'Connection to 127.0.0.1 timed out. (connect timeout=1.0)')': /status